<?xml version="1.0" ?>
<!-- =================================================================================== -->
<!-- |    This document was autogenerated by xacro from src/part1_gazebo/urdf/rrbot.xacro | -->
<!-- |    EDITING THIS FILE BY HAND IS NOT RECOMMENDED                                 | -->
<!-- =================================================================================== -->
<!-- Revolute-Revolute Manipulator -->
<robot name="rrbot">
  <!-- Space btw top of beam and the each joint -->
  <!-- ros_control plugin -->
  <gazebo>
    <plugin filename="libgazebo_ros_control.so" name="gazebo_ros_control">
      <robotNamespace>/rrbot</robotNamespace>
      <robotSimType>gazebo_ros_control/DefaultRobotHWSim</robotSimType>
    </plugin>
  </gazebo>
  <!-- Link1 -->
  <gazebo reference="link1">
    <material>Gazebo/Orange</material>
  </gazebo>
  <!-- Link2 -->
  <gazebo reference="link2">
    <mu1>0.2</mu1>
    <mu2>0.2</mu2>
    <material>Gazebo/Black</material>
  </gazebo>
  <!-- Link3 -->
  <gazebo reference="link3">
    <mu1>0.2</mu1>
    <mu2>0.2</mu2>
    <material>Gazebo/Orange</material>
  </gazebo>
  <material name="black">
    <color rgba="0.0 0.0 0.0 1.0"/>
  </material>
  <material name="blue">
    <color rgba="0.0 0.0 0.8 1.0"/>
  </material>
  <material name="green">
    <color rgba="0.0 0.8 0.0 1.0"/>
  </material>
  <material name="grey">
    <color rgba="0.2 0.2 0.2 1.0"/>
  </material>
  <material name="orange">
    <color rgba="1.0 0.4235294117647059 0.0392156862745098 1.0"/>
  </material>
  <material name="brown">
    <color rgba="0.8705882352941177 0.8117647058823529 0.7647058823529411 1.0"/>
  </material>
  <material name="red">
    <color rgba="0.8 0.0 0.0 1.0"/>
  </material>
  <material name="white">
    <color rgba="1.0 1.0 1.0 1.0"/>
  </material>
  <!-- Used for fixing robot to Gazebo 'base_link' -->
  <link name="world"/>
  <joint name="fixed" type="fixed">
    <parent link="world"/>
    <child link="link1"/>
  </joint>
  <!-- Base Link -->
  <link name="link1">
    <collision>
      <origin rpy="0 0 0" xyz="0 0 1.0"/>
      <geometry>
        <box size="0.1 0.1 2"/>
      </geometry>
    </collision>
    <visual>
      <origin rpy="0 0 0" xyz="0 0 1.0"/>
      <geometry>
        <box size="0.1 0.1 2"/>
      </geometry>
      <material name="orange"/>
    </visual>
    <inertial>
      <origin rpy="0 0 0" xyz="0 0 1.0"/>
      <mass value="1"/>
      <inertia ixx="0.3341666666666666" ixy="0.0" ixz="0.0" iyy="0.3341666666666666" iyz="0.0" izz="0.001666666666666667"/>
    </inertial>
  </link>
  <joint name="joint1" type="revolute">
    <parent link="link1"/>
    <child link="link2"/>
    <origin rpy="0 0 0" xyz="0 0 2.0599999999999996"/>
    <limit effort="1000.0" lower="0.0" upper="0.548" velocity="0.5"/>
    <dynamics damping="0.7"/>
    <axis xyz="0 0 1"/>
  </joint>
  <!-- Middle Link -->
  <link name="link2">
    <collision>
      <origin rpy="0 0 0" xyz="0 0.5 0"/>
      <geometry>
        <box size="0.1 1 0.1"/>
      </geometry>
    </collision>
    <visual>
      <origin rpy="0 0 0" xyz="0 0.5 0"/>
      <geometry>
        <box size="0.1 1 0.1"/>
      </geometry>
      <material name="black"/>
    </visual>
    <inertial>
      <origin rpy="0 0 0" xyz="0 0.5 0"/>
      <mass value="1"/>
      <inertia ixx="0.08416666666666667" ixy="0.0" ixz="0.0" iyy="0.08416666666666667" iyz="0.0" izz="0.001666666666666667"/>
    </inertial>
  </link>
  <joint name="joint2" type="revolute">
    <parent link="link2"/>
    <child link="link3"/>
    <origin rpy="0 0 0" xyz="0 1 0.11"/>
    <axis xyz="0 0 1"/>
    <limit effort="1000.0" lower="0.0" upper="0.548" velocity="0.5"/>
    <dynamics damping="0.7"/>
  </joint>
  <!-- Top Link -->
  <link name="link3">
    <collision>
      <origin rpy="0 0 0" xyz="0 0.5 0"/>
      <geometry>
        <box size="0.1 1 0.1"/>
      </geometry>
    </collision>
    <visual>
      <origin rpy="0 0 0" xyz="0 0.5 0"/>
      <geometry>
        <box size="0.1 1 0.1"/>
      </geometry>
      <material name="orange"/>
    </visual>
    <inertial>
      <origin rpy="0 0 0" xyz="0 0.5 0"/>
      <mass value="1"/>
      <inertia ixx="0.08416666666666667" ixy="0.0" ixz="0.0" iyy="0.08416666666666667" iyz="0.0" izz="0.001666666666666667"/>
    </inertial>
  </link>
  <joint name="joint3" type="prismatic">
    <parent link="link3"/>
    <child link="link4"/>
    <origin rpy="0 0 0" xyz="0 1.06 0"/>
    <axis xyz="0 0 1"/>
    <limit effort="1000.0" lower="-1.0" upper="0.0" velocity="1.0"/>
    <dynamics damping="0.7"/>
  </joint>
  <link name="link4">
    <collision>
      <origin rpy="0 0 0" xyz="0 0 0.5"/>
      <geometry>
        <box size="0.1 0.1 1"/>
      </geometry>
    </collision>
    <visual>
      <origin rpy="0 0 0" xyz="0 0 0.5"/>
      <geometry>
        <box size="0.1 0.1 1"/>
      </geometry>
      <material name="black"/>
    </visual>
    <inertial>
      <origin rpy="0 0 0" xyz="0 0 0.5"/>
      <mass value="1"/>
      <inertia ixx="0.08416666666666667" ixy="0.0" ixz="0.0" iyy="0.08416666666666667" iyz="0.0" izz="0.001666666666666667"/>
    </inertial>
  </link>
</robot>

